2025-05-09 23:19:42,810 - __main__ - INFO - üöÄ Iniciando API em http://0.0.0.0:8000
2025-05-09 23:19:42,865 - __main__ - INFO - Inicializando SQLiDetector...
2025-05-09 23:19:42,887 - __main__ - INFO - üíæ Vetorizador fallback salvo em C:\apps\savm\src\models\text_features\vectorizer.joblib
2025-05-09 23:19:42,909 - __main__ - WARNING - ‚ö†Ô∏è Usando vetorizador fallback
2025-05-09 23:19:42,913 - __main__ - WARNING - ‚ö†Ô∏è Treinando novo modelo fallback
2025-05-09 23:19:43,078 - __main__ - INFO - üíæ Modelo fallback salvo em C:\apps\savm\src\models\fallback_model.joblib
2025-05-09 23:19:43,121 - __main__ - ERROR - Falha na verifica√ß√£o: Teste falhou para: SELECT * FROM users
2025-05-09 23:19:43,121 - __main__ - CRITICAL - Falha na inicializa√ß√£o: Sistema n√£o passou nos testes de verifica√ß√£o
Traceback (most recent call last):
  File "C:\apps\savm\src\models\sqli_detector.py", line 288, in _verify_system
    raise ValueError(f"Teste falhou para: {query}")
ValueError: Teste falhou para: SELECT * FROM users

The above exception was the direct cause of the following exception:

Traceback (most recent call last):
  File "C:\apps\savm\src\models\sqli_detector.py", line 392, in lifespan
    detector = SQLiDetector(config)
               ^^^^^^^^^^^^^^^^^^^^
  File "C:\apps\savm\src\models\sqli_detector.py", line 202, in __init__
    self._verify_system()
  File "C:\apps\savm\src\models\sqli_detector.py", line 291, in _verify_system
    raise RuntimeError("Sistema n√£o passou nos testes de verifica√ß√£o") from e
RuntimeError: Sistema n√£o passou nos testes de verifica√ß√£o
2025-05-09 23:27:23,293 - __main__ - INFO - üöÄ Iniciando API em http://0.0.0.0:8000
2025-05-09 23:27:23,342 - __main__ - INFO - Inicializando SQLiDetector...
2025-05-09 23:27:23,353 - __main__ - INFO - ‚úÖ Vetorizador carregado de C:\apps\savm\src\models\text_features\vectorizer.joblib
2025-05-09 23:27:23,395 - __main__ - INFO - ‚úÖ Modelo fallback carregado de C:\apps\savm\src\models\fallback_model.joblib
2025-05-09 23:27:23,443 - __main__ - WARNING - ‚ö†Ô∏è Teste n√£o esperado para: ' OR 1=1 -- (esperado: True, obtido: False)
2025-05-09 23:27:23,472 - __main__ - WARNING - ‚ö†Ô∏è Teste n√£o esperado para: SELECT 1 (esperado: False, obtido: True)
2025-05-09 23:27:23,499 - __main__ - WARNING - ‚ö†Ô∏è Teste n√£o esperado para: UPDATE users SET pass='123' (esperado: False, obtido: True)
2025-05-09 23:27:23,503 - __main__ - ERROR - ‚ùå Testes falharam (2/5 passaram)
2025-05-09 23:27:23,507 - __main__ - CRITICAL - Falha cr√≠tica na inicializa√ß√£o: Precis√£o do teste abaixo do m√≠nimo aceit√°vel (3 testes necess√°rios)
2025-05-09 23:27:23,507 - __main__ - WARNING - ‚ö†Ô∏è Usando detector m√≠nimo de fallback
2025-05-09 23:35:20,097 - __main__ - INFO - Iniciando API em http://0.0.0.0:8000
2025-05-09 23:35:20,181 - __main__ - INFO - Inicializando SQLiDetector...
2025-05-09 23:35:20,191 - __main__ - INFO - Vetorizador carregado de C:\apps\savm\src\models\text_features\vectorizer.joblib
2025-05-09 23:35:20,233 - __main__ - INFO - Modelo fallback carregado de C:\apps\savm\src\models\fallback_model.joblib
2025-05-09 23:35:20,284 - __main__ - WARNING - Teste nao esperado para: ' OR 1=1 -- (esperado: True, obtido: False)
2025-05-09 23:35:20,313 - __main__ - WARNING - Teste nao esperado para: SELECT 1 (esperado: False, obtido: True)
2025-05-09 23:35:20,335 - __main__ - WARNING - Teste nao esperado para: UPDATE users SET pass='123' (esperado: False, obtido: True)
2025-05-09 23:35:20,336 - __main__ - ERROR - Testes falharam (2/5 passaram)
2025-05-09 23:35:20,336 - __main__ - INFO - SQLiDetector inicializado com sucesso
